Workbook

Sheet 概要
A1: Home Depot Product Search Relevance：実験の振り返り（exp001〜exp033）
A3: タスク | B3: 検索語と商品のペアの関連度 relevance（1〜3、複数人の評価の平均）を予測する。評価指標は RMSE
A4: 期間 | B4: 2026-10-13 〜 2026-10-28
A5: 現在のベスト | B5: exp033_all：LightGBM 単体（全部の列）。CV 0.41705 / Private LB 0.41978 / Public LB 0.42182
A6: 最初のベースライン | B6: exp001：CV 0.50579 / Private LB 0.50782（ベストまで −0.0880）
A7: ベストの構成 | B7: 前処理（正規化・SymSpell・ステミング）→ TF-IDF・BM25・単語一致・文字 n-gram・ブランド・属性値 → 埋め込み（mxbai-embed-large）→ 学習前の cross-encoder（mxbai-rerank-base）→ ファインチューニングした cross-encoder 8 種（bge-reranker-base ×2、v2-m3 ×2（種の平均）、DeBERTa ×2、ModernBERT ×1、Qwen3 ×1）→ 同じ検索語の中での相対値 → LightGBM（Optuna で調整、lr 0.02）
A8: CV の方針 | B8: 検索語単位の GroupKFold（5 分割）。test の 73% の行は train にない検索語で、train では 1 つの検索語が平均 6〜7 行出てくるため
A9: データの要点 | B9: test の 57% の行は train にない商品。11.6% は train のどの商品より新しい（product_uid > 206,650）。新しい商品ほど relevance が低く、誤差が大きい。同じ検索語でほぼ同じ商品の組でも評価のばらつきが RMSE 換算で 0.288 あり、ラベルのノイズが大きい
A10: 最大の課題 | B10: ファインチューニングのスコアへの依存を強める変更（アンサンブル、種の平均、数値だけの特徴量）ほど、CV は良くなるのに LB は良くならない。CV では train より新しい商品を評価できない。採否は Public LB で判断している
A11: 環境 | B11: RTX 5070 Laptop（8GB、電源アダプタ次第で 25W 制限）。.venv-gpu（transformers 5.20）と .venv-deberta（transformers 4.49、DeBERTa の学習用）。長時間の処理はツールの 2 時間制限のため独立プロセスで実行
A12: 詳細 | B12: 各実験の詳細は EXPERIMENTS.md、コードは exp/・src/・scripts/
A14: シートの説明
A15: 実験一覧 | B15: 全実験の CV・LB・比較対象からの変化（数式）・判定・メモ
A16: ファインチューニング比較 | B16: ファインチューニングした cross-encoder ごとの単独の精度と時間
A17: 学び | B17: 実験から得た教訓と、その根拠になった実験
A18: CV と LB | B18: 提出した実験の CV と Private LB の推移（表とグラフ）

Sheet 実験一覧
A1: No | B1: 実験 | C1: 日付 | D1: カテゴリ | E1: 内容 | F1: 比較対象 | G1: CV RMSE | H1: Private LB | I1: Public LB | J1: LB−CV (Private) | K1: CV の変化 (比較対象から) | L1: Private LB の変化 (比較対象から) | M1: 判定 | N1: メモ・学び | O1: スクリプト / 出力
A2: 1 | B2: exp001 | C2: 2026-10-13 | D2: ベースライン | E2: TF-IDF コサイン類似度（検索語×タイトル、検索語×説明文）＋ LightGBM | G2: 0.50579 | H2: 0.50782 | J2: =IF(H2="","",H2-G2) | K2: =IF(F2="","",G2-INDEX($G:$G,MATCH(F2,$B:$B,0))) | L2: =IF(OR(F2="",H2=""),"",IFERROR(IF(INDEX($H:$H,MATCH(F2,$B:$B,0))="","",H2-INDEX($H:$H,MATCH(F2,$B:$B,0))),"")) | M2: 採用（基準） | N2: 特徴量 2 つだけ。CV の分け方は検索語単位の GroupKFold（test の 73% は train にない検索語） | O2: exp/exp001_tfidf_lgbm.py
A3: 2 | B3: exp002 | C3: 2026-10-15 | D3: 特徴量 | E3: ＋ 検索語・タイトルの TF-IDF ベクトル（疎行列のまま） | F3: exp001 | G3: 0.49581 | H3: 0.49333 | J3: =IF(H3="","",H3-G3) | K3: =IF(F3="","",G3-INDEX($G:$G,MATCH(F3,$B:$B,0))) | L3: =IF(OR(F3="",H3=""),"",IFERROR(IF(INDEX($H:$H,MATCH(F3,$B:$B,0))="","",H3-INDEX($H:$H,MATCH(F3,$B:$B,0))),"")) | M3: 採用 | N3: for/in/to など「検索語の形」や商品カテゴリの単語が効いた | O3: exp/exp002_tfidf_vec_lgbm.py
A4: 3 | B4: exp003 | C4: 2026-10-15 | D4: 前処理 | E4: ＋ 表記の正規化（連結語・単位・寸法・ハイフン）＋ Snowball ステミング | F4: exp002 | G4: 0.48587 | J4: =IF(H4="","",H4-G4) | K4: =IF(F4="","",G4-INDEX($G:$G,MATCH(F4,$B:$B,0))) | L4: =IF(OR(F4="",H4=""),"",IFERROR(IF(INDEX($H:$H,MATCH(F4,$B:$B,0))="","",H4-INDEX($H:$H,MATCH(F4,$B:$B,0))),"")) | M4: 採用 | N4: 語彙が 1/3 に。1 文字の数字を残したことも効いた | O4: exp/exp003_preprocess.py
A5: 4 | B5: exp004 | C5: 2026-10-15 | D5: スペル修正 | E5: ＋ 検索語のスペル修正（SymSpell、商品テキストの語彙を辞書に） | F5: exp003 | G5: 0.48211 | H5: 0.47993 | J5: =IF(H5="","",H5-G5) | K5: =IF(F5="","",G5-INDEX($G:$G,MATCH(F5,$B:$B,0))) | L5: =IF(OR(F5="",H5=""),"",IFERROR(IF(INDEX($H:$H,MATCH(F5,$B:$B,0))="","",H5-INDEX($H:$H,MATCH(F5,$B:$B,0))),"")) | M5: 採用 | N5: 修正が入るのは 14% の行。ブランド名に強い | O5: exp/exp004_spell_symspell.py
A6: 5 | B6: exp005 | C6: 2026-10-15 | D6: スペル修正 | E6: exp003 ＋ 検索語のスペル修正（ローカル LLM：Llama 3.1 8B） | F6: exp004 | G6: 0.4825 | H6: 0.48024 | J6: =IF(H6="","",H6-G6) | K6: =IF(F6="","",G6-INDEX($G:$G,MATCH(F6,$B:$B,0))) | L6: =IF(OR(F6="",H6=""),"",IFERROR(IF(INDEX($H:$H,MATCH(F6,$B:$B,0))="","",H6-INDEX($H:$H,MATCH(F6,$B:$B,0))),"")) | M6: 不採用 | N6: SymSpell とほぼ同等。修正結果の一致は 55% で得意分野が違う（LLM は一般語・文脈、SymSpell は商品の語彙） | O6: exp/exp005_spell_llm.py
A7: 6 | B7: exp006 | C7: 2026-10-16 | D7: 特徴量 | E7: ＋ 単語一致の数え上げ（18 個）＋ ブランド一致（4 個） | F7: exp004 | G7: 0.46648 | H7: 0.46501 | J7: =IF(H7="","",H7-G7) | K7: =IF(F7="","",G7-INDEX($G:$G,MATCH(F7,$B:$B,0))) | L7: =IF(OR(F7="",H7=""),"",IFERROR(IF(INDEX($H:$H,MATCH(F7,$B:$B,0))="","",H7-INDEX($H:$H,MATCH(F7,$B:$B,0))),"")) | M7: 採用 | N7: 単純な「何割一致したか」が 1 位に。最後の単語の一致、別ブランドの言及が効いた | O7: exp/exp006_match_brand.py
A8: 7 | B8: exp007 | C8: 2026-10-16 | D8: 特徴量 | E8: ＋ BM25 ＋ 文字 n-gram の類似度 ＋ 属性値との一致 | F8: exp006 | G8: 0.46387 | H8: 0.46273 | J8: =IF(H8="","",H8-G8) | K8: =IF(F8="","",G8-INDEX($G:$G,MATCH(F8,$B:$B,0))) | L8: =IF(OR(F8="",H8=""),"",IFERROR(IF(INDEX($H:$H,MATCH(F8,$B:$B,0))="","",H8-INDEX($H:$H,MATCH(F8,$B:$B,0))),"")) | M8: 採用 | N8: 文字 n-gram が 2 位。属性値はほぼ効かない | O8: exp/exp007_bm25_char_attr.py
A9: 8 | B9: exp008 | C9: 2026-10-16 | D9: 特徴量 | E9: ＋ ブランド名の TF-IDF（類似度 ＋ ベクトル） | F9: exp007 | G9: 0.46364 | J9: =IF(H9="","",H9-G9) | K9: =IF(F9="","",G9-INDEX($G:$G,MATCH(F9,$B:$B,0))) | L9: =IF(OR(F9="",H9=""),"",IFERROR(IF(INDEX($H:$H,MATCH(F9,$B:$B,0))="","",H9-INDEX($H:$H,MATCH(F9,$B:$B,0))),"")) | M9: 不採用 | N9: 誤差の範囲。exp006 のブランド特徴量・タイトルと情報が重なる | O9: exp/exp008_brand_tfidf.py
A10: 9 | B10: exp009 | C10: 2026-10-16 | D10: 埋め込み | E10: exp007 ＋ 埋め込み（nomic-embed-text、Ollama）の類似度 ＋ ベクトル | F10: exp007 | G10: 0.45262 | H10: 0.45013 | J10: =IF(H10="","",H10-G10) | K10: =IF(F10="","",G10-INDEX($G:$G,MATCH(F10,$B:$B,0))) | L10: =IF(OR(F10="",H10=""),"",IFERROR(IF(INDEX($H:$H,MATCH(F10,$B:$B,0))="","",H10-INDEX($H:$H,MATCH(F10,$B:$B,0))),"")) | M10: 採用 | N10: 意味の近さ（同義語）を拾える。単独の相関 0.428 は当時の最高 | O10: exp/exp009_embedding.py
A11: 10 | B11: exp010 | C11: 2026-10-16 | D11: 埋め込み | E11: exp007 ＋ 埋め込み（mxbai-embed-large、GPU で直接計算）＋ 説明文のベクトルも | F11: exp009 | G11: 0.44584 | H11: 0.44345 | J11: =IF(H11="","",H11-G11) | K11: =IF(F11="","",G11-INDEX($G:$G,MATCH(F11,$B:$B,0))) | L11: =IF(OR(F11="",H11=""),"",IFERROR(IF(INDEX($H:$H,MATCH(F11,$B:$B,0))="","",H11-INDEX($H:$H,MATCH(F11,$B:$B,0))),"")) | M11: 採用 | N11: PyTorch で GPU を直接使い 84 分 → 33 分 | O11: exp/exp010_embedding_mxbai.py
A12: 11 | B12: exp011 | C12: 2026-10-17 | D12: 検証 | E12: exp009（nomic）＋ 説明文の埋め込みベクトル | F12: exp009 | G12: 0.45252 | J12: =IF(H12="","",H12-G12) | K12: =IF(F12="","",G12-INDEX($G:$G,MATCH(F12,$B:$B,0))) | L12: =IF(OR(F12="",H12=""),"",IFERROR(IF(INDEX($H:$H,MATCH(F12,$B:$B,0))="","",H12-INDEX($H:$H,MATCH(F12,$B:$B,0))),"")) | M12: 検証 | N12: 説明文のベクトルは効果なし → exp010 の改善はモデルの変更によるもの。gain が大きくても予測を良くしているとは限らない | O12: exp/exp011_nomic_desc_vec.py
A13: 12 | B13: exp012 | C13: 2026-10-17 | D13: 検証 | E13: exp010 から説明文の埋め込みベクトルを外す | F13: exp010 | G13: 0.44593 | J13: =IF(H13="","",H13-G13) | K13: =IF(F13="","",G13-INDEX($G:$G,MATCH(F13,$B:$B,0))) | L13: =IF(OR(F13="",H13=""),"",IFERROR(IF(INDEX($H:$H,MATCH(F13,$B:$B,0))="","",H13-INDEX($H:$H,MATCH(F13,$B:$B,0))),"")) | M13: 採用 | N13: 精度は同じで列数・時間を削減 | O13: exp/exp012_mxbai_no_desc_vec.py
A14: 13 | B14: exp013 | C14: 2026-10-17 | D14: リランカー | E14: ＋ cross-encoder（ms-marco-MiniLM-L-6-v2）のスコア | F14: exp012 | G14: 0.44496 | J14: =IF(H14="","",H14-G14) | K14: =IF(F14="","",G14-INDEX($G:$G,MATCH(F14,$B:$B,0))) | L14: =IF(OR(F14="",H14=""),"",IFERROR(IF(INDEX($H:$H,MATCH(F14,$B:$B,0))="","",H14-INDEX($H:$H,MATCH(F14,$B:$B,0))),"")) | M14: 不採用 | N14: 軽量モデルでは効果小。exp014 に置き換え | O14: exp/exp013_rerank_minilm.py
A15: 14 | B15: exp014 | C15: 2026-10-17 | D15: リランカー | E15: ＋ cross-encoder（mxbai-rerank-base-v1、DeBERTa）のスコア（学習前のまま） | F15: exp012 | G15: 0.44025 | J15: =IF(H15="","",H15-G15) | K15: =IF(F15="","",G15-INDEX($G:$G,MATCH(F15,$B:$B,0))) | L15: =IF(OR(F15="",H15=""),"",IFERROR(IF(INDEX($H:$H,MATCH(F15,$B:$B,0))="","",H15-INDEX($H:$H,MATCH(F15,$B:$B,0))),"")) | M15: 採用 | N15: 説明文のスコアで MiniLM に大差 | O15: exp/exp014_rerank_mxbai.py
A16: 15 | B16: exp015 | C16: 2026-10-17 | D16: リランカー | E16: exp014 ＋ MiniLM のスコアも両方 | F16: exp014 | G16: 0.44011 | J16: =IF(H16="","",H16-G16) | K16: =IF(F16="","",G16-INDEX($G:$G,MATCH(F16,$B:$B,0))) | L16: =IF(OR(F16="",H16=""),"",IFERROR(IF(INDEX($H:$H,MATCH(F16,$B:$B,0))="","",H16-INDEX($H:$H,MATCH(F16,$B:$B,0))),"")) | M16: 不採用 | N16: 同じ種類の情報で上乗せなし | O16: exp/exp015_rerank_both.py
A17: 16 | B17: exp016 | C17: 2026-10-17 | D17: チューニング | E17: LightGBM のハイパーパラメータを Optuna で調整（30 回）＋ learning_rate 0.02 | F17: exp014 | G17: 0.43841 | H17: 0.4371 | J17: =IF(H17="","",H17-G17) | K17: =IF(F17="","",G17-INDEX($G:$G,MATCH(F17,$B:$B,0))) | L17: =IF(OR(F17="",H17=""),"",IFERROR(IF(INDEX($H:$H,MATCH(F17,$B:$B,0))="","",H17-INDEX($H:$H,MATCH(F17,$B:$B,0))),"")) | M17: 採用 | N17: 小さく慎重な木 + 強い L1 + feature_fraction 0.31。改善の大半はパラメータ（lr の効果は −0.0003） | O17: exp/exp016_tuning.py
A18: 17 | B18: exp017 | C18: 2026-10-18 | D18: 特徴量 | E18: ＋ 同じ検索語の中で比べた相対的な特徴量（平均・最大との差、順位） | F18: exp016 | G18: 0.43582 | H18: 0.43452 | J18: =IF(H18="","",H18-G18) | K18: =IF(F18="","",G18-INDEX($G:$G,MATCH(F18,$B:$B,0))) | L18: =IF(OR(F18="",H18=""),"",IFERROR(IF(INDEX($H:$H,MATCH(F18,$B:$B,0))="","",H18-INDEX($H:$H,MATCH(F18,$B:$B,0))),"")) | M18: 採用 | N18: 手軽で効果大。q_size（検索語の商品数）はデータの作り方由来の偏り | O18: exp/exp017_query_relative.py
A19: 18 | B19: exp018 | C19: 2026-10-18 | D19: ファインチューニング | E19: ＋ ファインチューニングした cross-encoder（bge-reranker-base、検索語×タイトル、out-of-fold） | F19: exp017 | G19: 0.42836 | H19: 0.4281 | J19: =IF(H19="","",H19-G19) | K19: =IF(F19="","",G19-INDEX($G:$G,MATCH(F19,$B:$B,0))) | L19: =IF(OR(F19="",H19=""),"",IFERROR(IF(INDEX($H:$H,MATCH(F19,$B:$B,0))="","",H19-INDEX($H:$H,MATCH(F19,$B:$B,0))),"")) | M19: 採用 | N19: 単独で相関 0.554。DeBERTa（mxbai-rerank）は transformers 5.x で NaN になり断念 | O19: exp/exp018_finetune_ce.py
A20: 19 | B20: exp019 | C20: 2026-10-18 | D20: 特徴量 | E20: ＋ 検索語とタイトルの主語（商品の種類）の一致 | F20: exp018 | G20: 0.42835 | J20: =IF(H20="","",H20-G20) | K20: =IF(F20="","",G20-INDEX($G:$G,MATCH(F20,$B:$B,0))) | L20: =IF(OR(F20="",H20=""),"",IFERROR(IF(INDEX($H:$H,MATCH(F20,$B:$B,0))="","",H20-INDEX($H:$H,MATCH(F20,$B:$B,0))),"")) | M20: 不採用 | N20: 誤差分析の「付属品の取り違え」は、実はラベルのノイズだった | O20: exp/exp019_head_match.py
A21: 20 | B21: exp020 | C21: 2026-10-18 | D21: ファインチューニング | E21: ＋ ファインチューニング（bge-reranker-base、検索語×タイトル + 説明文） | F21: exp018 | G21: 0.42615 | H21: 0.42668 | J21: =IF(H21="","",H21-G21) | K21: =IF(F21="","",G21-INDEX($G:$G,MATCH(F21,$B:$B,0))) | L21: =IF(OR(F21="",H21=""),"",IFERROR(IF(INDEX($H:$H,MATCH(F21,$B:$B,0))="","",H21-INDEX($H:$H,MATCH(F21,$B:$B,0))),"")) | M21: 採用 | N21: 説明文を入れると単独で −0.0046。この頃から LB が CV より悪くなり始める | O21: exp/exp020_finetune_ce_desc.py
A22: 21 | B22: exp021 | C22: 2026-10-19 | D22: ファインチューニング | E22: ＋ 大きいモデル（bge-reranker-v2-m3、タイトル） | F22: exp020 | G22: 0.42283 | J22: =IF(H22="","",H22-G22) | K22: =IF(F22="","",G22-INDEX($G:$G,MATCH(F22,$B:$B,0))) | L22: =IF(OR(F22="",H22=""),"",IFERROR(IF(INDEX($H:$H,MATCH(F22,$B:$B,0))="","",H22-INDEX($H:$H,MATCH(F22,$B:$B,0))),"")) | M22: 採用 | N22: 単語の埋め込み層の固定 + 8bit AdamW で 8GB に収めた（約 8 倍速） | O22: exp/exp021_finetune_ce_large.py
A23: 22 | B23: exp022 | C23: 2026-10-19 | D23: ファインチューニング | E23: ＋ 大きいモデル（v2-m3、タイトル + 説明文） | F23: exp021 | G23: 0.42098 | H23: 0.42315 | J23: =IF(H23="","",H23-G23) | K23: =IF(F23="","",G23-INDEX($G:$G,MATCH(F23,$B:$B,0))) | L23: =IF(OR(F23="",H23=""),"",IFERROR(IF(INDEX($H:$H,MATCH(F23,$B:$B,0))="","",H23-INDEX($H:$H,MATCH(F23,$B:$B,0))),"")) | M23: 採用 | N23: 予測を fp32 でまとめて行うとメモリがあふれ停滞 → bf16 予測に修正 | O23: exp/exp022_finetune_ce_large_desc.py
A24: 23 | B24: exp023 | C24: 2026-10-19 | D24: アンサンブル | E24: 24 メンバー（LGB/XGB/Cat/Ridge/RF/ET/kNN/MLP）を OOF で重み最適化 | F24: exp022 | G24: 0.41938 | H24: 0.42338 | J24: =IF(H24="","",H24-G24) | K24: =IF(F24="","",G24-INDEX($G:$G,MATCH(F24,$B:$B,0))) | L24: =IF(OR(F24="",H24=""),"",IFERROR(IF(INDEX($H:$H,MATCH(F24,$B:$B,0))="","",H24-INDEX($H:$H,MATCH(F24,$B:$B,0))),"")) | M24: 不採用 | N24: CV では改善したが LB は悪化。重みは Ridge・MLP・RF など LGB と性質の違うモデルに集中 | O24: exp/exp023_blend.py
A25: 24 | B25: exp024_lgb | C25: 2026-10-19 | D25: 検証・対策 | E25: test のファインチューニングのスコアを fold ごとのモデルの予測にそろえる（LightGBM 単体） | F25: exp022 | G25: 0.42099 | H25: 0.42257 | I25: 0.42444 | J25: =IF(H25="","",H25-G25) | K25: =IF(F25="","",G25-INDEX($G:$G,MATCH(F25,$B:$B,0))) | L25: =IF(OR(F25="",H25=""),"",IFERROR(IF(INDEX($H:$H,MATCH(F25,$B:$B,0))="","",H25-INDEX($H:$H,MATCH(F25,$B:$B,0))),"")) | M25: 採用 | N25: train は 1 モデルの予測、test は 5 モデルの平均というずれを解消。LB −0.0006 | O25: output/exp024/submission_lgb.csv
A26: 25 | B26: exp024_blend | C26: 2026-10-19 | D26: 検証・対策 | E26: 同上（アンサンブル） | F26: exp023 | G26: 0.4192 | H26: 0.42282 | I26: 0.42485 | J26: =IF(H26="","",H26-G26) | K26: =IF(F26="","",G26-INDEX($G:$G,MATCH(F26,$B:$B,0))) | L26: =IF(OR(F26="",H26=""),"",IFERROR(IF(INDEX($H:$H,MATCH(F26,$B:$B,0))="","",H26-INDEX($H:$H,MATCH(F26,$B:$B,0))),"")) | M26: 不採用 | N26: 対策で LB −0.0006 だが LGB 単体に及ばず | O26: exp/exp024_blend.py
A27: 26 | B27: exp025_lgb | C27: 2026-10-20 | D27: ファインチューニング | E27: v2-m3（タイトル + 説明文）を 2 つの種で平均（LightGBM 単体） | F27: exp024_lgb | G27: 0.4203 | J27: =IF(H27="","",H27-G27) | K27: =IF(F27="","",G27-INDEX($G:$G,MATCH(F27,$B:$B,0))) | L27: =IF(OR(F27="",H27=""),"",IFERROR(IF(INDEX($H:$H,MATCH(F27,$B:$B,0))="","",H27-INDEX($H:$H,MATCH(F27,$B:$B,0))),"")) | M27: 採用 | N27: 単独 0.43708 → 0.43407。8 時間の不在中に独立プロセスで実行 | O27: output/exp025/submission_lgb.csv
A28: 27 | B28: exp026_lgb | C28: 2026-10-20 | D28: ファインチューニング | E28: v2-m3（タイトルのみ）も 2 つの種で平均（LightGBM 単体） | F28: exp025_lgb | G28: 0.42015 | H28: 0.42254 | I28: 0.42439 | J28: =IF(H28="","",H28-G28) | K28: =IF(F28="","",G28-INDEX($G:$G,MATCH(F28,$B:$B,0))) | L28: =IF(OR(F28="",H28=""),"",IFERROR(IF(INDEX($H:$H,MATCH(F28,$B:$B,0))="","",H28-INDEX($H:$H,MATCH(F28,$B:$B,0))),"")) | M28: 採用 | N28: 種の平均は CV では効くが LB にはほぼ効かず | O28: output/exp026/submission_lgb.csv
A29: 28 | B29: exp026_blend | C29: 2026-10-20 | D29: アンサンブル | E29: 同上（アンサンブル） | F29: exp024_blend | G29: 0.41854 | H29: 0.42268 | I29: 0.42461 | J29: =IF(H29="","",H29-G29) | K29: =IF(F29="","",G29-INDEX($G:$G,MATCH(F29,$B:$B,0))) | L29: =IF(OR(F29="",H29=""),"",IFERROR(IF(INDEX($H:$H,MATCH(F29,$B:$B,0))="","",H29-INDEX($H:$H,MATCH(F29,$B:$B,0))),"")) | M29: 不採用 | N29: LGB 単体に及ばず | O29: exp/exp026_run.py
A30: 29 | B30: exp027 | C30: 2026-10-20 | D30: 特徴量選択 | E30: LightGBM で数値の特徴量 80 列だけ使う（埋め込み・TF-IDF ベクトルを外す） | F30: exp026_lgb | G30: 0.41776 | H30: 0.42354 | I30: 0.42547 | J30: =IF(H30="","",H30-G30) | K30: =IF(F30="","",G30-INDEX($G:$G,MATCH(F30,$B:$B,0))) | L30: =IF(OR(F30="",H30=""),"",IFERROR(IF(INDEX($H:$H,MATCH(F30,$B:$B,0))="","",H30-INDEX($H:$H,MATCH(F30,$B:$B,0))),"")) | M30: 不採用 | N30: CV −0.0024 なのに LB +0.0010。ファインチューニングのスコアへの依存を強めると LB で悪化 | O30: output/exp027/submission_num.csv
A31: 30 | B31: exp028_all | C31: 2026-10-21 | D31: 検証・対策 | E31: train にある検索語の test 行は、その検索語を見ていない fold のモデルのスコアを使う | F31: exp026_lgb | G31: 0.42015 | H31: 0.4234 | I31: 0.42529 | J31: =IF(H31="","",H31-G31) | K31: =IF(F31="","",G31-INDEX($G:$G,MATCH(F31,$B:$B,0))) | L31: =IF(OR(F31="",H31=""),"",IFERROR(IF(INDEX($H:$H,MATCH(F31,$B:$B,0))="","",H31-INDEX($H:$H,MATCH(F31,$B:$B,0))),"")) | M31: 不採用 | N31: 仮説は外れ。見た検索語の高めのスコアは正しい情報だった | O31: output/exp028/submission_all.csv
A32: 31 | B32: exp028_num | C32: 2026-10-21 | D32: 検証・対策 | E32: 同上（数値の特徴量だけ） | F32: exp027 | G32: 0.41776 | H32: 0.42434 | I32: 0.42636 | J32: =IF(H32="","",H32-G32) | K32: =IF(F32="","",G32-INDEX($G:$G,MATCH(F32,$B:$B,0))) | L32: =IF(OR(F32="",H32=""),"",IFERROR(IF(INDEX($H:$H,MATCH(F32,$B:$B,0))="","",H32-INDEX($H:$H,MATCH(F32,$B:$B,0))),"")) | M32: 不採用 | N32: 同上 | O32: output/exp028/submission_num.csv
A33: 32 | B33: exp029_all | C33: 2026-10-27 | D33: ファインチューニング | E33: ＋ ファインチューニングした DeBERTa（mxbai-rerank-base-v1、タイトル + 説明文、transformers 4.49） | F33: exp026_lgb | G33: 0.41812 | H33: 0.42011 | I33: 0.42207 | J33: =IF(H33="","",H33-G33) | K33: =IF(F33="","",G33-INDEX($G:$G,MATCH(F33,$B:$B,0))) | L33: =IF(OR(F33="",H33=""),"",IFERROR(IF(INDEX($H:$H,MATCH(F33,$B:$B,0))="","",H33-INDEX($H:$H,MATCH(F33,$B:$B,0))),"")) | M33: 採用 | N33: 1.8 億で v2-m3（5.7 億）と同精度。系統の違うモデルは LB でもしっかり効く。学習は 7 時間（GPU メモリがあふれ気味） | O33: output/exp029/submission_all.csv
A34: 33 | B34: exp029_num | C34: 2026-10-27 | D34: 特徴量選択 | E34: 同上（数値の特徴量 84 列だけ、参考） | F34: exp029_all | G34: 0.41547 | J34: =IF(H34="","",H34-G34) | K34: =IF(F34="","",G34-INDEX($G:$G,MATCH(F34,$B:$B,0))) | L34: =IF(OR(F34="",H34=""),"",IFERROR(IF(INDEX($H:$H,MATCH(F34,$B:$B,0))="","",H34-INDEX($H:$H,MATCH(F34,$B:$B,0))),"")) | M34: 参考 | N34: 未提出 | O34: output/exp029/submission_num.csv
A35: 34 | B35: exp030_all | C35: 2026-10-28 | D35: ファインチューニング | E35: ＋ ファインチューニングした DeBERTa（検索語 × タイトル） | F35: exp029_all | G35: 0.41776 | H35: 0.41998 | I35: 0.42198 | J35: =IF(H35="","",H35-G35) | K35: =IF(F35="","",G35-INDEX($G:$G,MATCH(F35,$B:$B,0))) | L35: =IF(OR(F35="",H35=""),"",IFERROR(IF(INDEX($H:$H,MATCH(F35,$B:$B,0))="","",H35-INDEX($H:$H,MATCH(F35,$B:$B,0))),"")) | M35: 採用 | N35: LB はわずかに改善（Public −0.00009）。単独 0.43951 はタイトル版で最良。ただし DeBERTa（タイトル + 説明文）との相関 0.945 で、CV の上乗せは −0.0004 と小さい。学習は 1 時間 | O35: output/exp030/submission_all.csv
A36: 35 | B36: exp030_num | C36: 2026-10-28 | D36: 特徴量選択 | E36: 同上（数値の特徴量 88 列だけ、参考） | F36: exp030_all | G36: 0.41521 | J36: =IF(H36="","",H36-G36) | K36: =IF(F36="","",G36-INDEX($G:$G,MATCH(F36,$B:$B,0))) | L36: =IF(OR(F36="",H36=""),"",IFERROR(IF(INDEX($H:$H,MATCH(F36,$B:$B,0))="","",H36-INDEX($H:$H,MATCH(F36,$B:$B,0))),"")) | M36: 参考 | N36: 未提出 | O36: output/exp030/submission_num.csv
A37: 36 | B37: exp031_all | C37: 2026-10-28 | D37: ファインチューニング | E37: exp029 ＋ ファインチューニングした ModernBERT（gte-reranker-modernbert-base、タイトル + 説明文） | F37: exp029_all | G37: 0.41743 | H37: 0.4199 | I37: 0.42184 | J37: =IF(H37="","",H37-G37) | K37: =IF(F37="","",G37-INDEX($G:$G,MATCH(F37,$B:$B,0))) | L37: =IF(OR(F37="",H37=""),"",IFERROR(IF(INDEX($H:$H,MATCH(F37,$B:$B,0))="","",H37-INDEX($H:$H,MATCH(F37,$B:$B,0))),"")) | M37: 採用 | N37: LB で Public −0.00023、新しいベスト（exp030 とは別に exp029 に加えたもの）。別系統のリランカー。単独 0.43602 は全モデルで最良（1.5 億パラメータ）。ほかとの相関 0.87〜0.93。学習は 2 時間 40 分 | O37: output/exp031/submission_all.csv
A38: 37 | B38: exp031_num | C38: 2026-10-28 | D38: 特徴量選択 | E38: 同上（数値の特徴量 88 列だけ、参考） | F38: exp031_all | G38: 0.41496 | J38: =IF(H38="","",H38-G38) | K38: =IF(F38="","",G38-INDEX($G:$G,MATCH(F38,$B:$B,0))) | L38: =IF(OR(F38="",H38=""),"",IFERROR(IF(INDEX($H:$H,MATCH(F38,$B:$B,0))="","",H38-INDEX($H:$H,MATCH(F38,$B:$B,0))),"")) | M38: 参考 | N38: 未提出 | O38: output/exp031/submission_num.csv
A39: 38 | B39: exp032_all | C39: 2026-10-28 | D39: ファインチューニング | E39: exp029 ＋ ファインチューニングした Qwen3-Reranker-0.6B（LLM 系、タイトル） | F39: exp029_all | G39: 0.41759 | H39: 0.42004 | I39: 0.42201 | J39: =IF(H39="","",H39-G39) | K39: =IF(F39="","",G39-INDEX($G:$G,MATCH(F39,$B:$B,0))) | L39: =IF(OR(F39="",H39=""),"",IFERROR(IF(INDEX($H:$H,MATCH(F39,$B:$B,0))="","",H39-INDEX($H:$H,MATCH(F39,$B:$B,0))),"")) | M39: 採用 | N39: LB はごくわずかに改善（Public −0.00006）。CV の改善ほど LB には効かず。単独 0.44286 と弱めだが、ほかとの相関が最も低い（0.86〜0.90）。モデル固有の入力の形が必要。gradient checkpointing なしではメモリがあふれ 30W に。学習は 6 時間 | O39: output/exp032/submission_all.csv
A40: 39 | B40: exp032_num | C40: 2026-10-28 | D40: 特徴量選択 | E40: 同上（数値の特徴量 88 列だけ、参考） | F40: exp032_all | G40: 0.4151 | J40: =IF(H40="","",H40-G40) | K40: =IF(F40="","",G40-INDEX($G:$G,MATCH(F40,$B:$B,0))) | L40: =IF(OR(F40="",H40=""),"",IFERROR(IF(INDEX($H:$H,MATCH(F40,$B:$B,0))="","",H40-INDEX($H:$H,MATCH(F40,$B:$B,0))),"")) | M40: 参考 | N40: 未提出 | O40: output/exp032/submission_num.csv
...

Sheet ファインチューニング比較
A1: モデル | B1: 系統 | C1: パラメータ数 | D1: 入力 | E1: 学習の工夫 | F1: 単独の OOF RMSE | G1: relevance との相関 | H1: 学習時間（5 fold） | I1: 使用した実験 | J1: 備考
A2: bge-reranker-base | B2: XLM-RoBERTa | C2: 2.8 億 | D2: タイトル | E2: — | F2: 0.44997 | G2: 0.554 | H2: 29 分 | I2: exp018〜
A3: bge-reranker-base | B3: XLM-RoBERTa | C3: 2.8 億 | D3: タイトル + 説明文（256） | E3: — | F3: 0.44534 | G3: 0.567 | H3: 178 分 | I3: exp020〜
A4: bge-reranker-v2-m3 | B4: XLM-RoBERTa | C4: 5.7 億 | D4: タイトル | E4: 埋め込み層を固定 + 8bit AdamW | F4: 0.44113 | G4: 0.574 | H4: 65 分 | I4: exp021〜
A5: bge-reranker-v2-m3（2 つの種の平均） | B5: XLM-RoBERTa | C5: 5.7 億 ×2 | D5: タイトル | E5: 同上 | F5: 0.43792 | H5: +66 分 | I5: exp026〜 | J5: 種の相関 0.958
A6: bge-reranker-v2-m3 | B6: XLM-RoBERTa | C6: 5.7 億 | D6: タイトル + 説明文（256） | E6: 同上 + バッチ 8 × 4 + bf16 予測 | F6: 0.43708 | G6: 0.585 | H6: 283 分 | I6: exp022〜
A7: bge-reranker-v2-m3（2 つの種の平均） | B7: XLM-RoBERTa | C7: 5.7 億 ×2 | D7: タイトル + 説明文（256） | E7: 同上 | F7: 0.43407 | H7: +4.7 時間 | I7: exp025〜 | J7: 種の相関 0.964
A8: mxbai-rerank-base-v1 | B8: DeBERTa-v3 | C8: 1.8 億 | D8: タイトル（128） | E8: transformers 4.49 の別環境。バッチ 16 × 2 | F8: 0.43951 | H8: 1 時間 | I8: exp030 | J8: DeBERTa（タイトル + 説明文）との相関 0.945
A9: mxbai-rerank-base-v1 | B9: DeBERTa-v3 | C9: 1.8 億 | D9: タイトル + 説明文（256） | E9: transformers 4.49 の別環境。バッチ 16 × 2 | F9: 0.43702 | H9: 7 時間 | I9: exp029 | J9: transformers 5.x では NaN。ほかのスコアとの相関 0.88〜0.92
A10: gte-reranker-modernbert-base | B10: ModernBERT | C10: 1.5 億 | D10: タイトル + 説明文（256） | E10: —（.venv-gpu のまま） | F10: 0.43602 | G10: 0.582 | H10: 2 時間 40 分 | I10: exp031 | J10: ほかのスコアとの相関 0.87〜0.93
A11: Qwen3-Reranker-0.6B（seq-cls） | B11: Qwen3（LLM） | C11: 6 億 | D11: タイトル（160、指示文の形で包む） | E11: 埋め込み層を固定 + 8bit AdamW + gradient checkpointing | F11: 0.44286 | G11: 0.561 | H11: 6 時間 | I11: exp032 | J11: ほかのスコアとの相関 0.86〜0.90（最も低い）
A12: （学習前）mxbai-rerank-base-v1 | B12: DeBERTa-v3 | C12: 1.8 億 | D12: タイトル | E12: ファインチューニングなし | G12: 0.433 | H12: 51 分（採点のみ） | I12: exp014〜 | J12: 参考

Sheet 学び
A1: No | B1: 学び | C1: 根拠の実験
A2: 1 | B2: CV の分け方は test との関係に合わせる。test の 73% が未知の検索語なので、検索語単位の GroupKFold にした | C2: exp001〜
A3: 2 | B3: 単純な特徴量（単語一致の割合、最後の単語の一致など）が、複雑な類似度より効くことがある | C3: exp006
A4: 3 | B4: 意味の近さ（埋め込み）と、ペアを同時に読む cross-encoder は大きく効く。cross-encoder はファインチューニングでさらに伸びる | C4: exp009, exp014, exp018
A5: 4 | B5: gain（重要度）が大きい特徴量でも、予測を良くしているとは限らない。入れた場合と外した場合を比べて確かめる | C5: exp011, exp012
A6: 5 | B6: 誤差分析で目立った「付属品の取り違え」の多くは、実はラベルのノイズだった。大きく外した行は、同じ商品群の評価のばらつきも確かめる | C6: exp019
A7: 6 | B7: ラベルを使う特徴量（スタッキング）は、2 段目と同じ fold で out-of-fold にしないとリークする。fold の一致はコードで確かめる | C7: exp018
A8: 7 | B8: train と test で特徴量の作り方をそろえる（OOF は 1 モデル、test も fold ごとに 1 モデル）と LB が改善した | C8: exp024
A9: 8 | B9: ファインチューニングのスコアへの依存を強める変更（アンサンブル、種の平均、数値だけ）は、CV では良くても LB では効かない・悪化する。CV では train より新しい商品を評価できない | C9: exp023, exp025〜exp028
A10: 9 | B10: 一方、系統の違うモデル（DeBERTa）を加えると、CV 以上に LB が改善した。同じ系統を重ねるより、系統を増やすほうが頑健 | C10: exp029
A11: 10 | B11: 系統の違うモデルを加える効果は、加えるほど小さくなる（DeBERTa は LB −0.0024、次の ModernBERT は −0.0002）。同じ系統で入力だけ変えた版（DeBERTa タイトル）はさらに小さい | C11: exp029, exp030, exp031
A12: 11 | B12: スコアの相関が低い（性質が違う）だけでは LB に効くとは限らない。単独で弱いモデル（Qwen3-0.6B）は CV では効いたが LB ではごくわずか。単独の強さと性質の違いの両方が要る | C12: exp031, exp032
A13: 12 | B13: 仮説（見た検索語のスコアの偏り）は LB で否定された。仮説は小さく試し、外れたら記録して戻す | C13: exp028
... A17: 16 | B17: 長時間の処理は、ツールの 2 時間制限を避けて独立プロセスで実行し、fold ごとに保存して途中から再開できるようにする | C17: exp025, exp026, exp029

Sheet CV と LB
A1: 実験 | B1: CV RMSE | C1: Private LB | D1: LB−CV
A2: =実験一覧!B2 | B2: =実験一覧!G2 | C2: =実験一覧!H2 | D2: =C2-B2
A3: =実験一覧!B3 | B3: =実験一覧!G3 | C3: =実験一覧!H3 | D3: =C3-B3
A4: =実験一覧!B5 | B4: =実験一覧!G5 | C4: =実験一覧!H5 | D4: =C4-B4
A5: =実験一覧!B6 | B5: =実験一覧!G6 | C5: =実験一覧!H6 | D5: =C5-B5
A6: =実験一覧!B7 | B6: =実験一覧!G7 | C6: =実験一覧!H7 | D6: =C6-B6
A7: =実験一覧!B8 | B7: =実験一覧!G8 | C7: =実験一覧!H8 | D7: =C7-B7
A8: =実験一覧!B10 | B8: =実験一覧!G10 | C8: =実験一覧!H10 | D8: =C8-B8
A9: =実験一覧!B11 | B9: =実験一覧!G11 | C9: =実験一覧!H11 | D9: =C9-B9
A10: =実験一覧!B17 | B10: =実験一覧!G17 | C10: =実験一覧!H17 | D10: =C10-B10
A11: =実験一覧!B18 | B11: =実験一覧!G18 | C11: =実験一覧!H18 | D11: =C11-B11
A12: =実験一覧!B19 | B12: =実験一覧!G19 | C12: =実験一覧!H19 | D12: =C12-B12
A13: =実験一覧!B21 | B13: =実験一覧!G21 | C13: =実験一覧!H21 | D13: =C13-B13
A14: =実験一覧!B23 | B14: =実験一覧!G23 | C14: =実験一覧!H23 | D14: =C14-B14
A15: =実験一覧!B24 | B15: =実験一覧!G24 | C15: =実験一覧!H24 | D15: =C15-B15
A16: =実験一覧!B25 | B16: =実験一覧!G25 | C16: =実験一覧!H25 | D16: =C16-B16
A17: =実験一覧!B26 | B17: =実験一覧!G26 | C17: =実験一覧!H26 | D17: =C17-B17
A18: =実験一覧!B28 | B18: =実験一覧!G28 | C18: =実験一覧!H28 | D18: =C18-B18
A19: =実験一覧!B29 | B19: =実験一覧!G29 | C19: =実験一覧!H29 | D19: =C19-B19
A20: =実験一覧!B30 | B20: =実験一覧!G30 | C20: =実験一覧!H30 | D20: =C20-B20
A21: =実験一覧!B31 | B21: =実験一覧!G31 | C21: =実験一覧!H31 | D21: =C21-B21
A22: =実験一覧!B32 | B22: =実験一覧!G32 | C22: =実験一覧!H32 | D22: =C22-B22
A23: =実験一覧!B33 | B23: =実験一覧!G33 | C23: =実験一覧!H33 | D23: =C23-B23
A24: =実験一覧!B35 | B24: =実験一覧!G35 | C24: =実験一覧!H35 | D24: =C24-B24
A25: =実験一覧!B37 | B25: =実験一覧!G37 | C25: =実験一覧!H37 | D25: =C25-B25
A26: =実験一覧!B39 | B26: =実験一覧!G39 | C26: =実験一覧!H39 | D26: =C26-B26
A27: =実験一覧!B41 | B27: =実験一覧!G41 | C27: =実験一覧!H41 | D27: =C27-B27
A29: 緑の文字は「実験一覧」シートへの参照。LB−CV が正なら、LB が CV より悪い
